Workbook
Name months: OFFSET(data_mthly!$E$6:$E$2276,0,0,COUNTIF(data_mthly!$E:$E,">0"),1)
Name threeyrave: OFFSET(data_wkly!$C$632:$C$2300,0,0,COUNTIF(data_wkly!$C:$C,">0")-528,1)
Name weeks: IF(data_wkly!C1048570=data_wkly!XFD1048570,OFFSET(data_wkly!$C$6:$C$2300,0,0,COUNTIF(data_wkly!$C:$C,">0")-1,1),OFFSET(data_wkly!$C$6:$C$2300,0,0,COUNTIF(data_wkly!$C:$C,">0")-0,1))
Name wks_wtbnds: OFFSET(data_wkly!$C$671:$C$2300,0,0,COUNTIF(data_wkly!$C:$C,">0")-665,1)

Sheet data_wkly
A1: EU update week ending | B1: 46235 | D1: SPP update week ending | F1: 46228 | G1: SPP_EU_ave | H1: SPP_UK_price | I1: #REF! | J1: 9 | L1: Last update | M1: 46234 | O1: 46235 | AC1: 45668
A2: EU update week commencing | B2: 20260726 | D2: SPP_throughput | E2: SPP_EU_price | F2: SPP_EU_ave | G2: SPP_EU_ave | H2: SPP_UK_price | I2: SPP_UK_ave | J2: SPP_UK_ave | K2: SPP_EU_weight | L2: SPP_probe | M2: APP_throughput | N2: APP_EU_price | P2: APP_EU_ave | Q2: APP_UK_price | R2: APP_UK_ave | S2: APP_UK_ave | T2: APP_EU_weight | U2: APP_probe | W2: EU_price | Y2: EXUK_EU_price | AA2: EU_S_price | AC2: EXUK_EU_S_price | AO2: Up to 60 | AP2: 60 to 69.9 | AQ2: 70 to 79.9 | AR2: 80 to 89.9 | AS2: 90 to 99.9 | AT2: 100 to 104.9 | AU2: 105 and over | AV2: All pigs | AW2: 70 to 104.9 | AX2: Column12 | AY2: Up to 60_1 | AZ2: 60 to 69.9_2 | BA2: 70 to 79.9_3 | BB2: 80 to 89.9_4 | BC2: 90 to 99.9_5 | BD2: 100 to 104.9_6 | BE2: 105 and over_7 | BF2: All pigs_8 | BG2: 70 to 104.9_9 | BN2: update | BO2: SPP | BP2: 46228 | BQ2: 46232
D3: GB Standard Pig price (SPP) | M3: GB All pig price (APP) | W3: EU Grade E pig price | AA3: EU Grade S pig price | AF3: GB Deadweight Average Pig price (DAPP) - 2007 to 2014 | AO3: SPP volume | AY3: SPP average EU spec price | BI3: SPP volume | BK3: SPP average EU spec price | BN3: update | BO3: EU | BP3: 46235 | BQ3: 46234
B4: Week commencing | C4: Week ending | D4: Throughput | E4: EU Spec | H4: UK spec | K4: Carcase | M4: Throughput | N4: EU spec | Q4: UK spec | T4: Carcase | W4: EU28 | Y4: (excl. UK) pig price | AA4: EU28 | AC4: (excl. UK) pig price | AF4: EU spec | AI4: UK spec | AL4: Carcase | AO4: Weight bands (kg) | AY4: Weight bands (kg) | BI4: Weight bands (kg)
A5: 7 | E5: Price | F5: Change on week | G5: 3 year average | H5: Price | I5: Change on week | J5: 3 year average | K5: Weight (EU) | L5: Probe | N5: Price | O5: Change on week | P5: 3 year average | Q5: Price | R5: Change on week | S5: 3 year average | T5: Weight (EU) | U5: Probe | W5: Price | X5: Change on week | Y5: Price | Z5: Change on week | AA5: Price | AB5: Change on week | AC5: Price | AD5: Change on week | AF5: Price | AG5: Change on week | AH5: 3 year average | AI5: Price | AJ5: Change on week | AK5: 3 year average | AL5: Weight (EU) | AM5: Probe | AO5: Up to 60 | AP5: 60 to 69.9 | AQ5: 70 to 79.9 | AR5: 80 to 89.9 | AS5: 90 to 99.9 | AT5: 100 to 104.9 | AU5: 105 and over | AV5: All pigs | AW5: 70 to 104.9 | AY5: Up to 60 | AZ5: 60 to 69.9 | BA5: 70 to 79.9 | BB5: 80 to 89.9 | BC5: 90 to 99.9 | BD5: 100 to 104.9 | BE5: 105 and over | BF5: All pigs | BG5: 70 to 104.9 | BI5: 70 to 99.9* | BJ5: 100 and over* | BK5: 70 to 99.9* | BL5: 100 and over*
A6: 2007_1 | B6: 20061231 | C6: 39088 | AF6: 107.69 | AG6: -0.14 | AI6: 105.99 | AJ6: na
A7: 2007_2 | B7: 20070107 | C7: 39095 | AF7: 107.44 | AG7: -0.25 | AI7: 105.75 | AJ7: -0.24
A8: 2007_3 | B8: 20070114 | C8: 39102 | AF8: 106.4 | AG8: -1.04 | AI8: 104.72 | AJ8: -1.03
A9: 2007_4 | B9: 20070121 | C9: 39109 | AF9: 105.71 | AG9: -0.69 | AI9: 104.05 | AJ9: -0.67
A10: 2007_5 | B10: 20070128 | C10: 39116 | AF10: 105.02 | AG10: -0.69 | AI10: 103.37 | AJ10: -0.68
A11: 2007_6 | B11: 20070204 | C11: 39123 | AF11: 104.83 | AG11: -0.19 | AI11: 103.18 | AJ11: -0.19
A12: 2007_7 | B12: 20070211 | C12: 39130 | AF12: 104.49 | AG12: -0.34 | AI12: 102.84 | AJ12: -0.34
A13: 2007_8 | B13: 20070218 | C13: 39137 | AF13: 104.38 | AG13: -0.11 | AI13: 102.74 | AJ13: -0.1
A14: 2007_9 | B14: 20070225 | C14: 39144 | AF14: 104.46 | AG14: 0.08 | AI14: 102.81 | AJ14: 0.07
A15: 2007_10 | B15: 20070304 | C15: 39151 | AF15: 104.73 | AG15: 0.27 | AI15: 103.08 | AJ15: 0.27
A16: 2007_11 | B16: 20070311 | C16: 39158 | AF16: 105.3 | AG16: 0.57 | AI16: 103.64 | AJ16: 0.56
A17: 2007_12 | B17: 20070318 | C17: 39165 | AF17: 105.28 | AG17: -0.02 | AI17: 103.62 | AJ17: -0.02
A18: 2007_13 | B18: 20070325 | C18: 39172 | AF18: 105.81 | AG18: 0.53 | AI18: 104.14 | AJ18: 0.52
... A69: 2008_12 | B69: 20080316 | C69: 39529 | AF69: 114.29 | AG69: 0.7 | AI69: 112.23 | AJ69: 0.43
A70: 2008_13 | B70: 20080323 | C70: 39536 | AF70: 114.87 | AG70: 0.58 | AI70: 112.81 | AJ70: 0.58
A71: 2008_14 | B71: 20080330 | C71: 39543 | AF71: 116.27 | AG71: 1.4 | AI71: 114.2 | AJ71: 1.39
A72: 2008_15 | B72: 20080406 | C72: 39550 | AF72: 117.46 | AG72: 1.19 | AI72: 115.37 | AJ72: 1.17
A73: 2008_16 | B73: 20080413 | C73: 39557 | AF73: 118.05 | AG73: 0.59 | AI73: 115.95 | AJ73: 0.58
A74: 2008_17 | B74: 20080420 | C74: 39564 | AF74: 118.87 | AG74: 0.82 | AI74: 116.76 | AJ74: 0.81
A75: 2008_18 | B75: 20080427 | C75: 39571 | AF75: 119.47 | AG75: 0.6 | AI75: 117.34 | AJ75: 0.58
A76: 2008_19 | B76: 20080504 | C76: 39578 | AF76: 121.01 | AG76: 1.54 | AI76: 118.86 | AJ76: 1.52
A77: 2008_20 | B77: 20080511 | C77: 39585 | AF77: 121.97 | AG77: 0.96 | AI77: 119.8 | AJ77: 0.94
A78: 2008_21 | B78: 20080518 | C78: 39592 | AF78: 123.76 | AG78: 1.79 | AI78: 121.57 | AJ78: 1.77
A79: 2008_22 | B79: 20080525 | C79: 39599 | AF79: 124.91 | AG79: 1.15 | AI79: 122.7 | AJ79: 1.13
A80: 2008_23 | B80: 20080601 | C80: 39606 | AF80: 126.96 | AG80: 2.05 | AI80: 124.7 | AJ80: 2
A81: 2008_24 | B81: 20080608 | C81: 39613 | AF81: 129.22 | AG81: 2.26 | AI81: 126.94 | AJ81: 2.24
A82: 2008_25 | B82: 20080615 | C82: 39620 | AF82: 131.45 | AG82: 2.23 | AI82: 129.13 | AJ82: 2.19
A83: 2008_26 | B83: 20080622 | C83: 39627 | AF83: 133 | AG83: 1.55 | AI83: 130.65 | AJ83: 1.52
A84: 2008_27 | B84: 20080629 | C84: 39634 | AF84: 135.05 | AG84: 2.05 | AI84: 132.66 | AJ84: 2.01
A85: 2008_28 | B85: 20080706 | C85: 39641 | AF85: 135.6 | AG85: 0.55 | AI85: 133.2 | AJ85: 0.54
A86: 2008_29 | B86: 20080713 | C86: 39648 | AF86: 136.37 | AG86: 0.77 | AI86: 133.95 | AJ86: 0.75
A87: 2008_30 | B87: 20080720 | C87: 39655 | AF87: 137.22 | AG87: 0.85 | AI87: 134.77 | AJ87: 0.82
A88: 2008_31 | B88: 20080727 | C88: 39662 | AF88: 137.38 | AG88: 0.16 | AI88: 134.93 | AJ88: 0.16
A89: 2008_32 | B89: 20080803 | C89: 39669 | AF89: 136.85 | AG89: -0.53 | AI89: 134.41 | AJ89: -0.52
A90: 2008_33 | B90: 20080810 | C90: 39676 | AF90: 136.99 | AG90: 0.14 | AI90: 134.54 | AJ90: 0.13
...

Sheet data_mthly
A1: Last update | B1: 46204 | D1: SPP update month | F1: 46174 | G1: Percentage change | H1: -0.0064225532 | I1: -0.1410014 | K1: -0.0066942115 | L1: -0.14088629 | N1: APP update month | P1: 45627 | Q1: -0.0025958416 | R1: -0.028216393 | T1: -0.00273539 | U1: -0.027991895
F2: SPP_tp | G2: SPP_EU_price | J2: SPP_UK_price | M2: SPP_EU_weight | N2: SPP_probe | O2: APP_tp | P2: APP_EU_price | S2: APP_UK_price | V2: APP_EU_weight | W2: APP_probe
B3: Year | C3: Stat month start | D3: No weeks in stat month | E3: Month | F3: GB Standard Pig price (SPP) | O3: GB All Pig price (APP) | Y3: GB Deadweight Average Pig price (DAPP) - 2007 to 2014
F4: Throughput | G4: Euro spec | J4: UK spec | M4: Carcasse | O4: Throughput | P4: Euro spec | S4: UK spec | V4: Carcasse | Y4: Euro spec | AB4: UK spec | AE4: Carcasse
G5: Price | H5: Change on month | I5: Change on year | J5: Price | K5: Change on month | L5: Change on year | M5: Weight (EU) | N5: Probe | P5: Price | Q5: Change on month | R5: Change on year | S5: Price | T5: Change on month | U5: Change on year | V5: Weight (EU) | W5: Probe | Y5: Price | Z5: Change on month | AA5: Change on year | AB5: Price | AC5: Change on month | AD5: Change on year | AE5: Weight (EU) | AF5: Probe
B6: 2007 | E6: 39083 | Y6: 106.45 | AB6: 104.78 | AE6: 78.4 | AF6: 11
B7: 2007 | E7: 39114 | Y7: 104.54 | Z7: -1.91 | AB7: 102.89 | AC7: -1.89 | AE7: 78.6 | AF7: 10.9
B8: 2007 | E8: 39142 | Y8: 105.28 | Z8: 0.74 | AB8: 103.62 | AC8: 0.73 | AE8: 78.2 | AF8: 10.7
B9: 2007 | E9: 39173 | Y9: 106.4 | Z9: 1.12 | AB9: 104.73 | AC9: 1.11 | AE9: 78.2 | AF9: 10.8
B10: 2007 | E10: 39203 | Y10: 108.13 | Z10: 1.73 | AB10: 106.43 | AC10: 1.7 | AE10: 77.6 | AF10: 10.9
B11: 2007 | E11: 39234 | Y11: 109.55 | Z11: 1.42 | AB11: 107.82 | AC11: 1.39 | AE11: 77.3 | AF11: 11
B12: 2007 | E12: 39264 | Y12: 109.96 | Z12: 0.41 | AB12: 108.23 | AC12: 0.41 | AE12: 77.5 | AF12: 10.9
B13: 2007 | E13: 39295 | Y13: 109.37 | Z13: -0.59 | AB13: 107.64 | AC13: -0.59 | AE13: 79.6 | AF13: 11.1
B14: 2007 | E14: 39326 | Y14: 108.52 | Z14: -0.85 | AB14: 106.81 | AC14: -0.83 | AE14: 81.2 | AF14: 11.2
B15: 2007 | E15: 39356 | Y15: 109.04 | Z15: 0.52 | AB15: 107.33 | AC15: 0.52 | AE15: 81.77 | AF15: 11.2
B16: 2007 | E16: 39387 | Y16: 108.99 | Z16: -0.05 | AB16: 107.27 | AC16: -0.06 | AE16: 81.13 | AF16: 11.2
B17: 2007 | E17: 39417 | Y17: 110.17 | Z17: 1.18 | AB17: 108.44 | AC17: 1.17 | AE17: 79.76 | AF17: 11.1
B18: 2008 | E18: 39448 | Y18: 110.34 | Z18: 0.17 | AA18: 3.89 | AB18: 108.6 | AC18: 0.16 | AD18: 3.82 | AE18: 79.7 | AF18: 10.9
B19: 2008 | E19: 39479 | Y19: 111.85 | Z19: 1.51 | AA19: 7.31 | AB19: 110.09 | AC19: 1.49 | AD19: 7.2 | AE19: 78.68 | AF19: 10.7
B20: 2008 | E20: 39508 | Y20: 113.91 | Z20: 2.06 | AA20: 8.63 | AB20: 112.05 | AC20: 1.96 | AD20: 8.43 | AE20: 77.99 | AF20: 10.5
B21: 2008 | E21: 39539 | Y21: 118 | Z21: 4.09 | AA21: 11.6 | AB21: 115.9 | AC21: 3.85 | AD21: 11.17 | AE21: 77.48 | AF21: 10.5
B22: 2008 | E22: 39569 | Y22: 122.87 | Z22: 4.87 | AA22: 14.74 | AB22: 120.69 | AC22: 4.79 | AD22: 14.26 | AE22: 76.92 | AF22: 10.5
B23: 2008 | E23: 39600 | Y23: 130.21 | Z23: 7.34 | AA23: 20.66 | AB23: 127.9 | AC23: 7.21 | AD23: 20.08 | AE23: 76.69 | AF23: 10.7
B24: 2008 | E24: 39630 | Y24: 136.31 | Z24: 6.1 | AA24: 26.35 | AB24: 133.89 | AC24: 5.99 | AD24: 25.66 | AE24: 77.15 | AF24: 10.8
B25: 2008 | E25: 39661 | Y25: 136.7 | Z25: 0.39 | AA25: 27.33 | AB25: 134.26 | AC25: 0.37 | AD25: 26.62 | AE25: 78.03 | AF25: 11
B26: 2008 | E26: 39692 | Y26: 136.06 | Z26: -0.64 | AA26: 27.54 | AB26: 133.63 | AC26: -0.63 | AD26: 26.82 | AE26: 78.94 | AF26: 11.2
B27: 2008 | E27: 39722 | Y27: 135.86 | Z27: -0.2 | AA27: 26.82 | AB27: 133.42 | AC27: -0.21 | AD27: 26.09 | AE27: 78.81 | AF27: 11.3
B28: 2008 | E28: 39753 | Y28: 132.48 | Z28: -3.38 | AA28: 23.49 | AB28: 130.1 | AC28: -3.32 | AD28: 22.83 | AE28: 78.64 | AF28: 11.3
B29: 2008 | E29: 39783 | Y29: 131.14 | Z29: -1.34 | AA29: 20.97 | AB29: 128.81 | AC29: -1.29 | AD29: 20.37 | AE29: 76.8 | AF29: 11.1
... B41: 2009 | E41: 40148 | Y41: 138.79 | Z41: -1.22 | AA41: 7.65 | AB41: 136.31 | AC41: -1.18 | AD41: 7.5 | AE41: 78.76 | AF41: 11.2
B42: 2010 | C42: 40180 | D42: 4 | E42: 40179 | Y42: 138.89 | Z42: 0.1 | AA42: 7.43 | AB42: 136.4 | AC42: 0.09 | AD42: 7.29 | AE42: 79.55 | AF42: 11.1
B43: 2010 | C43: 40209 | D43: 4 | E43: 40210 | Y43: 140.92 | Z43: 2.03 | AA43: 3.78 | AB43: 138.39 | AC43: 1.99 | AD43: 3.7 | AE43: 79.49 | AF43: 10.9
B44: 2010 | C44: 40237 | D44: 4 | E44: 40238 | Y44: 142.13 | Z44: 1.21 | AA44: -0.19 | AB44: 139.57 | AC44: 1.18 | AD44: -0.22 | AE44: 79.44 | AF44: 10.9
B45: 2010 | C45: 40265 | D45: 5 | E45: 40269 | Y45: 143.6 | Z45: 1.47 | AA45: -4.7 | AB45: 141.02 | AC45: 1.45 | AD45: -4.63 | AE45: 79.23 | AF45: 10.9
B46: 2010 | C46: 40300 | D46: 4 | E46: 40299 | Y46: 145.22 | Z46: 1.62 | AA46: -6.85 | AB46: 142.62 | AC46: 1.6 | AD46: -6.73 | AE46: 78.64 | AF46: 10.8
B47: 2010 | C47: 40328 | D47: 4 | E47: 40330 | Y47: 146.77 | Z47: 1.55 | AA47: -7.27 | AB47: 144.15 | AC47: 1.53 | AD47: -7.15 | AE47: 78.11 | AF47: 10.9
B48: 2010 | C48: 40356 | D48: 5 | E48: 40360 | Y48: 146.54 | Z48: -0.23 | AA48: -8.73 | AB48: 143.92 | AC48: -0.23 | AD48: -8.58 | AE48: 78.05 | AF48: 11.2
B49: 2010 | C49: 40391 | D49: 4 | E49: 40391 | Y49: 143.74 | Z49: -2.8 | AA49: -9.32 | AB49: 141.16 | AC49: -2.76 | AD49: -9.16 | AE49: 78.92 | AF49: 11.3
B50: 2010 | C50: 40419 | D50: 4 | E50: 40422 | Y50: 141.43 | Z50: -2.31 | AA50: -8.62 | AB50: 138.88 | AC50: -2.28 | AD50: -8.48 | AE50: 79.73 | AF50: 11.3
B51: 2010 | C51: 40447 | D51: 5 | E51: 40452 | Y51: 138.57 | Z51: -2.86 | AA51: -7.05 | AB51: 136.07 | AC51: -2.81 | AD51: -6.93 | AE51: 80.11 | AF51: 11.4
...

Sheet Sheet6
U1: 43106
U2: 43470 | W2: APP_EU
J3: =YEAR(L3) -> 2014 | L3: 41730 | Q3: 41734 | U3: 43834 | W3: APP_UK
A4: Month | B4: Month start and end date | J4: =YEAR(L4) -> 2014 | L4: =EOMONTH(L3,0)+1 -> 41760 | Q4: =Q3+7 -> 41741 | U4: 44198 | W4: SPP_EU
C5: End date | D5: start_date | E5: end_date | F5: no_wks | J5: =YEAR(L5) -> 2014 | L5: =EOMONTH(L4,0)+1 -> 41791 | Q5: 41748 | U5: 44569 | W5: SPP_UK
J6: =YEAR(L6) -> 2014 | L6: =EOMONTH(L5,0)+1 -> 41821 | Q6: 41755 | U6: 44933
A7: 40179 | B7: 2/1/2010 - 30/1/2010 | D7: =DATE(H7,I7,G7) -> 40180 | E7: =D8-1 -> 40208 | F7: =ROUND((E7-D7)/7,0) -> 4 | G7: =LEFT(B7,FIND("/",B7)-1) -> 2 | H7: =RIGHT(TRIM(LEFT(B7,FIND("-",B7)-1)),4) -> 2010 | I7: =SUBSTITUTE(MID(SUBSTITUTE("/" & B7&REPT(" ",6),"/",REPT(",",255)),2*255,255),",","") -> 1 | J7: =YEAR(L7) -> 2014 | L7: =EOMONTH(L6,0)+1 -> 41852 | Q7: 41762 | U7: 45297
A8: 40210 | B8: 31/1/2010 - 27/2/2010 | D8: =DATE(H8,I8,G8) -> 40209 | E8: =D9-1 -> 40236 | F8: =ROUND((E8-D8)/7,0) -> 4 | G8: =LEFT(B8,FIND("/",B8)-1) -> 31 | H8: =RIGHT(TRIM(LEFT(B8,FIND("-",B8)-1)),4) -> 2010 | I8: =SUBSTITUTE(MID(SUBSTITUTE("/" & B8&REPT(" ",6),"/",REPT(",",255)),2*255,255),",","") -> 1 | J8: =YEAR(L8) -> 2014 | L8: =EOMONTH(L7,0)+1 -> 41883 | Q8: 41769 | U8: 46019
A9: 40238 | B9: 28/2/2010 - 27/3/2010 | D9: =DATE(H9,I9,G9) -> 40237 | E9: =D10-1 -> 40264 | F9: =ROUND((E9-D9)/7,0) -> 4 | G9: =LEFT(B9,FIND("/",B9)-1) -> 28 | H9: =RIGHT(TRIM(LEFT(B9,FIND("-",B9)-1)),4) -> 2010 | I9: =SUBSTITUTE(MID(SUBSTITUTE("/" & B9&REPT(" ",6),"/",REPT(",",255)),2*255,255),",","") -> 2 | J9: =YEAR(L9) -> 2014 | L9: =EOMONTH(L8,0)+1 -> 41913 | Q9: 41776
A10: 40269 | B10: 28/3/2010 - 1/5/2010 | D10: =DATE(H10,I10,G10) -> 40265 | E10: =D11-1 -> 40299 | F10: =ROUND((E10-D10)/7,0) -> 5 | G10: =LEFT(B10,FIND("/",B10)-1) -> 28 | H10: =RIGHT(TRIM(LEFT(B10,FIND("-",B10)-1)),4) -> 2010 | I10: =SUBSTITUTE(MID(SUBSTITUTE("/" & B10&REPT(" ",6),"/",REPT(",",255)),2*255,255),",","") -> 3 | J10: =YEAR(L10) -> 2014 | L10: =EOMONTH(L9,0)+1 -> 41944 | Q10: =Q9+7 -> 41783
A11: 40299 | B11: 2/5/2010 - 29/5/2010 | D11: =DATE(H11,I11,G11) -> 40300 | E11: =D12-1 -> 40327 | F11: =ROUND((E11-D11)/7,0) -> 4 | G11: =LEFT(B11,FIND("/",B11)-1) -> 2 | H11: =RIGHT(TRIM(LEFT(B11,FIND("-",B11)-1)),4) -> 2010 | I11: =SUBSTITUTE(MID(SUBSTITUTE("/" & B11&REPT(" ",6),"/",REPT(",",255)),2*255,255),",","") -> 5 | J11: =YEAR(L11) -> 2014 | L11: =EOMONTH(L10,0)+1 -> 41974 | Q11: 41790
A12: 40330 | B12: 30/5/2010 - 26/6/2010 | D12: =DATE(H12,I12,G12) -> 40328 | E12: =D13-1 -> 40355 | F12: =ROUND((E12-D12)/7,0) -> 4 | G12: =LEFT(B12,FIND("/",B12)-1) -> 30 | H12: =RIGHT(TRIM(LEFT(B12,FIND("-",B12)-1)),4) -> 2010 | I12: =SUBSTITUTE(MID(SUBSTITUTE("/" & B12&REPT(" ",6),"/",REPT(",",255)),2*255,255),",","") -> 5 | J12: =YEAR(L12) -> 2015 | L12: =EOMONTH(L11,0)+1 -> 42005 | Q12: =Q11+7 -> 41797
A13: 40360 | B13: 27/6/2010 - 31/7/2010 | D13: =DATE(H13,I13,G13) -> 40356 | E13: =D14-1 -> 40390 | F13: =ROUND((E13-D13)/7,0) -> 5 | G13: =LEFT(B13,FIND("/",B13)-1) -> 27 | H13: =RIGHT(TRIM(LEFT(B13,FIND("-",B13)-1)),4) -> 2010 | I13: =SUBSTITUTE(MID(SUBSTITUTE("/" & B13&REPT(" ",6),"/",REPT(",",255)),2*255,255),",","") -> 6 | J13: =YEAR(L13) -> 2015 | L13: =EOMONTH(L12,0)+1 -> 42036 | Q13: =Q12+7 -> 41804
A14: 40391 | B14: 1/8/2010 - 28/8/2010 | D14: =DATE(H14,I14,G14) -> 40391 | E14: =D15-1 -> 40418 | F14: =ROUND((E14-D14)/7,0) -> 4 | G14: =LEFT(B14,FIND("/",B14)-1) -> 1 | H14: =RIGHT(TRIM(LEFT(B14,FIND("-",B14)-1)),4) -> 2010 | I14: =SUBSTITUTE(MID(SUBSTITUTE("/" & B14&REPT(" ",6),"/",REPT(",",255)),2*255,255),",","") -> 8 | J14: =YEAR(L14) -> 2015 | L14: =EOMONTH(L13,0)+1 -> 42064 | Q14: 41811
A15: 40422 | B15: 29/8/2010 - 25/9/2010 | D15: =DATE(H15,I15,G15) -> 40419 | E15: =D16-1 -> 40446 | F15: =ROUND((E15-D15)/7,0) -> 4 | G15: =LEFT(B15,FIND("/",B15)-1) -> 29 | H15: =RIGHT(TRIM(LEFT(B15,FIND("-",B15)-1)),4) -> 2010 | I15: =SUBSTITUTE(MID(SUBSTITUTE("/" & B15&REPT(" ",6),"/",REPT(",",255)),2*255,255),",","") -> 8 | J15: =YEAR(L15) -> 2015 | L15: =EOMONTH(L14,0)+1 -> 42095 | Q15: 41818
A16: 40452 | B16: 26/9/2010 - 30/10/2010 | D16: =DATE(H16,I16,G16) -> 40447 | E16: =D17-1 -> 40481 | F16: =ROUND((E16-D16)/7,0) -> 5 | G16: =LEFT(B16,FIND("/",B16)-1) -> 26 | H16: =RIGHT(TRIM(LEFT(B16,FIND("-",B16)-1)),4) -> 2010 | I16: =SUBSTITUTE(MID(SUBSTITUTE("/" & B16&REPT(" ",6),"/",REPT(",",255)),2*255,255),",","") -> 9 | J16: =YEAR(L16) -> 2015 | L16: =EOMONTH(L15,0)+1 -> 42125 | Q16: 41825
A17: 40483 | B17: 31/10/2010 - 27/11/2010 | D17: =DATE(H17,I17,G17) -> 40482 | E17: =D18-1 -> 40509 | F17: =ROUND((E17-D17)/7,0) -> 4 | G17: =LEFT(B17,FIND("/",B17)-1) -> 31 | H17: =RIGHT(TRIM(LEFT(B17,FIND("-",B17)-1)),4) -> 2010 | I17: =SUBSTITUTE(MID(SUBSTITUTE("/" & B17&REPT(" ",6),"/",REPT(",",255)),2*255,255),",","") -> 10 | J17: =YEAR(L17) -> 2015 | L17: =EOMONTH(L16,0)+1 -> 42156 | Q17: 41832
A18: 40513 | B18: 28/11/2010 - 1/1/2011 | D18: =DATE(H18,I18,G18) -> 40510 | E18: =D19-1 -> 40544 | F18: =ROUND((E18-D18)/7,0) -> 5 | G18: =LEFT(B18,FIND("/",B18)-1) -> 28 | H18: =RIGHT(TRIM(LEFT(B18,FIND("-",B18)-1)),4) -> 2010 | I18: =SUBSTITUTE(MID(SUBSTITUTE("/" & B18&REPT(" ",6),"/",REPT(",",255)),2*255,255),",","") -> 11 | J18: =YEAR(L18) -> 2015 | L18: =EOMONTH(L17,0)+1 -> 42186 | Q18: 41839
A19: 40544 | B19: 2/1/2011 - 5/2/2011 | D19: =DATE(H19,I19,G19) -> 40545 | E19: =D20-1 -> 40579 | F19: =ROUND((E19-D19)/7,0) -> 5 | G19: =LEFT(B19,FIND("/",B19)-1) -> 2 | H19: =RIGHT(TRIM(LEFT(B19,FIND("-",B19)-1)),4) -> 2011 | I19: =SUBSTITUTE(MID(SUBSTITUTE("/" & B19&REPT(" ",6),"/",REPT(",",255)),2*255,255),",","") -> 1 | J19: =YEAR(L19) -> 2015 | L19: =EOMONTH(L18,0)+1 -> 42217 | Q19: 41846
A20: 40575 | B20: 6/2/2011 - 5/3/2011 | D20: =DATE(H20,I20,G20) -> 40580 | E20: =D21-1 -> 40607 | F20: =ROUND((E20-D20)/7,0) -> 4 | G20: =LEFT(B20,FIND("/",B20)-1) -> 6 | H20: =RIGHT(TRIM(LEFT(B20,FIND("-",B20)-1)),4) -> 2011 | I20: =SUBSTITUTE(MID(SUBSTITUTE("/" & B20&REPT(" ",6),"/",REPT(",",255)),2*255,255),",","") -> 2 | J20: =YEAR(L20) -> 2015 | L20: =EOMONTH(L19,0)+1 -> 42248 | Q20: 41853
A21: 40603 | B21: 6/3/2011 - 2/4/2011 | D21: =DATE(H21,I21,G21) -> 40608 | E21: =D22-1 -> 40635 | F21: =ROUND((E21-D21)/7,0) -> 4 | G21: =LEFT(B21,FIND("/",B21)-1) -> 6 | H21: =RIGHT(TRIM(LEFT(B21,FIND("-",B21)-1)),4) -> 2011 | I21: =SUBSTITUTE(MID(SUBSTITUTE("/" & B21&REPT(" ",6),"/",REPT(",",255)),2*255,255),",","") -> 3 | J21: =YEAR(L21) -> 2015 | L21: =EOMONTH(L20,0)+1 -> 42278 | Q21: 41860
A22: 40634 | B22: 3/4/2011 - 7/5/2011 | D22: =DATE(H22,I22,G22) -> 40636 | E22: =D23-1 -> 40670 | F22: =ROUND((E22-D22)/7,0) -> 5 | G22: =LEFT(B22,FIND("/",B22)-1) -> 3 | H22: =RIGHT(TRIM(LEFT(B22,FIND("-",B22)-1)),4) -> 2011 | I22: =SUBSTITUTE(MID(SUBSTITUTE("/" & B22&REPT(" ",6),"/",REPT(",",255)),2*255,255),",","") -> 4 | J22: =YEAR(L22) -> 2015 | L22: =EOMONTH(L21,0)+1 -> 42309 | Q22: 41867
A23: 40664 | B23: 8/5/2011 - 4/6/2011 | D23: =DATE(H23,I23,G23) -> 40671 | E23: =D24-1 -> 40698 | F23: =ROUND((E23-D23)/7,0) -> 4 | G23: =LEFT(B23,FIND("/",B23)-1) -> 8 | H23: =RIGHT(TRIM(LEFT(B23,FIND("-",B23)-1)),4) -> 2011 | I23: =SUBSTITUTE(MID(SUBSTITUTE("/" & B23&REPT(" ",6),"/",REPT(",",255)),2*255,255),",","") -> 5 | J23: =YEAR(L23) -> 2015 | L23: =EOMONTH(L22,0)+1 -> 42339 | Q23: 41874
A24: 40695 | B24: 5/6/2011 - 2/7/2011 | D24: =DATE(H24,I24,G24) -> 40699 | E24: =D25-1 -> 40726 | F24: =ROUND((E24-D24)/7,0) -> 4 | G24: =LEFT(B24,FIND("/",B24)-1) -> 5 | H24: =RIGHT(TRIM(LEFT(B24,FIND("-",B24)-1)),4) -> 2011 | I24: =SUBSTITUTE(MID(SUBSTITUTE("/" & B24&REPT(" ",6),"/",REPT(",",255)),2*255,255),",","") -> 6 | J24: =YEAR(L24) -> 2016 | L24: =EOMONTH(L23,0)+1 -> 42370 | Q24: 41881
A25: 40725 | B25: 3/7/2011 - 6/8/2011 | D25: =DATE(H25,I25,G25) -> 40727 | E25: =D26-1 -> 40761 | F25: =ROUND((E25-D25)/7,0) -> 5 | G25: =LEFT(B25,FIND("/",B25)-1) -> 3 | H25: =RIGHT(TRIM(LEFT(B25,FIND("-",B25)-1)),4) -> 2011 | I25: =SUBSTITUTE(MID(SUBSTITUTE("/" & B25&REPT(" ",6),"/",REPT(",",255)),2*255,255),",","") -> 7 | J25: =YEAR(L25) -> 2016 | L25: =EOMONTH(L24,0)+1 -> 42401 | Q25: 41888
... A28: 40817 | B28: 2/10/2011 - 5/11/2011 | D28: =DATE(H28,I28,G28) -> 40818 | E28: =D29-1 -> 40852 | F28: =ROUND((E28-D28)/7,0) -> 5 | G28: =LEFT(B28,FIND("/",B28)-1) -> 2 | H28: =RIGHT(TRIM(LEFT(B28,FIND("-",B28)-1)),4) -> 2011 | I28: =SUBSTITUTE(MID(SUBSTITUTE("/" & B28&REPT(" ",6),"/",REPT(",",255)),2*255,255),",","") -> 10 | J28: =YEAR(L28) -> 2016 | L28: =EOMONTH(L27,0)+1 -> 42491 | Q28: 41909
A29: 40848 | B29: 6/11/2011 - 3/12/2011 | D29: =DATE(H29,I29,G29) -> 40853 | E29: =D30-1 -> 40880 | F29: =ROUND((E29-D29)/7,0) -> 4 | G29: =LEFT(B29,FIND("/",B29)-1) -> 6 | H29: =RIGHT(TRIM(LEFT(B29,FIND("-",B29)-1)),4) -> 2011 | I29: =SUBSTITUTE(MID(SUBSTITUTE("/" & B29&REPT(" ",6),"/",REPT(",",255)),2*255,255),",","") -> 11 | J29: =YEAR(L29) -> 2016 | L29: =EOMONTH(L28,0)+1 -> 42522 | Q29: =Q28+7 -> 41916
A30: 40878 | B30: 4/12/2011 - 31/12/2011 | D30: =DATE(H30,I30,G30) -> 40881 | E30: =D31-1 -> 40908 | F30: =ROUND((E30-D30)/7,0) -> 4 | G30: =LEFT(B30,FIND("/",B30)-1) -> 4 | H30: =RIGHT(TRIM(LEFT(B30,FIND("-",B30)-1)),4) -> 2011 | I30: =SUBSTITUTE(MID(SUBSTITUTE("/" & B30&REPT(" ",6),"/",REPT(",",255)),2*255,255),",","") -> 12 | J30: =YEAR(L30) -> 2016 | L30: =EOMONTH(L29,0)+1 -> 42552 | Q30: =Q29+7 -> 41923
A31: 40909 | B31: 1/1/2012 - 4/2/2012 | D31: =DATE(H31,I31,G31) -> 40909 | E31: =D32-1 -> 40943 | F31: =ROUND((E31-D31)/7,0) -> 5 | G31: =LEFT(B31,FIND("/",B31)-1) -> 1 | H31: =RIGHT(TRIM(LEFT(B31,FIND("-",B31)-1)),4) -> 2012 | I31: =SUBSTITUTE(MID(SUBSTITUTE("/" & B31&REPT(" ",6),"/",REPT(",",255)),2*255,255),",","") -> 1 | J31: =YEAR(L31) -> 2016 | L31: =EOMONTH(L30,0)+1 -> 42583 | Q31: =Q30+7 -> 41930
A32: 40940 | B32: 5/2/2012 - 4/3/2012 | D32: =DATE(H32,I32,G32) -> 40944 | E32: =D33-1 -> 40972 | F32: =ROUND((E32-D32)/7,0) -> 4 | G32: =LEFT(B32,FIND("/",B32)-1) -> 5 | H32: =RIGHT(TRIM(LEFT(B32,FIND("-",B32)-1)),4) -> 2012 | I32: =SUBSTITUTE(MID(SUBSTITUTE("/" & B32&REPT(" ",6),"/",REPT(",",255)),2*255,255),",","") -> 2 | J32: =YEAR(L32) -> 2016 | L32: =EOMONTH(L31,0)+1 -> 42614 | Q32: =Q31+7 -> 41937
A33: 40969 | B33: 5/3/2012 - 1/4/2012 | D33: =DATE(H33,I33,G33) -> 40973 | E33: =D34-1 -> 41000 | F33: =ROUND((E33-D33)/7,0) -> 4 | G33: =LEFT(B33,FIND("/",B33)-1) -> 5 | H33: =RIGHT(TRIM(LEFT(B33,FIND("-",B33)-1)),4) -> 2012 | I33: =SUBSTITUTE(MID(SUBSTITUTE("/" & B33&REPT(" ",6),"/",REPT(",",255)),2*255,255),",","") -> 3 | J33: =YEAR(L33) -> 2016 | L33: =EOMONTH(L32,0)+1 -> 42644 | Q33: =Q32+7 -> 41944
A34: 41000 | B34: 2/4/2012 - 6/5/2012 | D34: =DATE(H34,I34,G34) -> 41001 | E34: =D35-1 -> 41035 | F34: =ROUND((E34-D34)/7,0) -> 5 | G34: =LEFT(B34,FIND("/",B34)-1) -> 2 | H34: =RIGHT(TRIM(LEFT(B34,FIND("-",B34)-1)),4) -> 2012 | I34: =SUBSTITUTE(MID(SUBSTITUTE("/" & B34&REPT(" ",6),"/",REPT(",",255)),2*255,255),",","") -> 4 | J34: =YEAR(L34) -> 2016 | L34: =EOMONTH(L33,0)+1 -> 42675 | Q34: =Q33+7 -> 41951
A35: 41030 | B35: 7/5/2012 - 3/6/2012 | D35: =DATE(H35,I35,G35) -> 41036 | E35: =D36-1 -> 41063 | F35: =ROUND((E35-D35)/7,0) -> 4 | G35: =LEFT(B35,FIND("/",B35)-1) -> 7 | H35: =RIGHT(TRIM(LEFT(B35,FIND("-",B35)-1)),4) -> 2012 | I35: =SUBSTITUTE(MID(SUBSTITUTE("/" & B35&REPT(" ",6),"/",REPT(",",255)),2*255,255),",","") -> 5 | J35: =YEAR(L35) -> 2016 | L35: =EOMONTH(L34,0)+1 -> 42705 | Q35: =Q34+7 -> 41958
A36: 41061 | B36: 4/6/2012 - 1/7/2012 | D36: =DATE(H36,I36,G36) -> 41064 | E36: =D37-1 -> 41091 | F36: =ROUND((E36-D36)/7,0) -> 4 | G36: =LEFT(B36,FIND("/",B36)-1) -> 4 | H36: =RIGHT(TRIM(LEFT(B36,FIND("-",B36)-1)),4) -> 2012 | I36: =SUBSTITUTE(MID(SUBSTITUTE("/" & B36&REPT(" ",6),"/",REPT(",",255)),2*255,255),",","") -> 6 | J36: =YEAR(L36) -> 2017 | L36: =EOMONTH(L35,0)+1 -> 42736 | Q36: =Q35+7 -> 41965
A37: 41091 | B37: 2/7/2012 - 5/8/2012 | D37: =DATE(H37,I37,G37) -> 41092 | E37: =D38-1 -> 41126 | F37: =ROUND((E37-D37)/7,0) -> 5 | G37: =LEFT(B37,FIND("/",B37)-1) -> 2 | H37: =RIGHT(TRIM(LEFT(B37,FIND("-",B37)-1)),4) -> 2012 | I37: =SUBSTITUTE(MID(SUBSTITUTE("/" & B37&REPT(" ",6),"/",REPT(",",255)),2*255,255),",","") -> 7 | J37: =YEAR(L37) -> 2017 | L37: =EOMONTH(L36,0)+1 -> 42767 | Q37: =Q36+7 -> 41972
A38: 41122 | B38: 6/8/2012 - 2/9/2012 | D38: =DATE(H38,I38,G38) -> 41127 | E38: =D39-1 -> 41154 | F38: =ROUND((E38-D38)/7,0) -> 4 | G38: =LEFT(B38,FIND("/",B38)-1) -> 6 | H38: =RIGHT(TRIM(LEFT(B38,FIND("-",B38)-1)),4) -> 2012 | I38: =SUBSTITUTE(MID(SUBSTITUTE("/" & B38&REPT(" ",6),"/",REPT(",",255)),2*255,255),",","") -> 8 | J38: =YEAR(L38) -> 2017 | L38: =EOMONTH(L37,0)+1 -> 42795 | Q38: =Q37+7 -> 41979
A39: 41153 | B39: 3/9/2012 - 30/9/2012 | D39: =DATE(H39,I39,G39) -> 41155 | E39: =D40-1 -> 41182 | F39: =ROUND((E39-D39)/7,0) -> 4 | G39: =LEFT(B39,FIND("/",B39)-1) -> 3 | H39: =RIGHT(TRIM(LEFT(B39,FIND("-",B39)-1)),4) -> 2012 | I39: =SUBSTITUTE(MID(SUBSTITUTE("/" & B39&REPT(" ",6),"/",REPT(",",255)),2*255,255),",","") -> 9 | J39: =YEAR(L39) -> 2017 | L39: =EOMONTH(L38,0)+1 -> 42826 | Q39: =Q38+7 -> 41986
A40: 41183 | B40: 1/10/2012 - 4/11/2012 | D40: =DATE(H40,I40,G40) -> 41183 | E40: =D41-1 -> 41217 | F40: =ROUND((E40-D40)/7,0) -> 5 | G40: =LEFT(B40,FIND("/",B40)-1) -> 1 | H40: =RIGHT(TRIM(LEFT(B40,FIND("-",B40)-1)),4) -> 2012 | I40: =SUBSTITUTE(MID(SUBSTITUTE("/" & B40&REPT(" ",6),"/",REPT(",",255)),2*255,255),",","") -> 10 | J40: =YEAR(L40) -> 2017 | L40: =EOMONTH(L39,0)+1 -> 42856 | Q40: =Q39+7 -> 41993
... A137: 44136 | B137: 01/11/2020 - 28/11/2020 | D137: =DATE(H137,I137,G137) -> 44136 | E137: =D138-1 -> 44163 | F137: =ROUND((E137-D137)/7,0) -> 4 | G137: =LEFT(B137,FIND("/",B137)-1) -> 01 | H137: =RIGHT(TRIM(LEFT(B137,FIND("-",B137)-1)),4) -> 2020 | I137: =SUBSTITUTE(MID(SUBSTITUTE("/" & B137&REPT(" ",6),"/",REPT(",",255)),2*255,255),",","") -> 11 | J137: =YEAR(L137) -> 2025 | L137: =EOMONTH(L136,0)+1 -> 45809 | Q137: =Q136+7 -> 42672
A138: 44166 | B138: 29/11/2020 - 26/12/2020 | D138: =DATE(H138,I138,G138) -> 44164 | E138: =D139-1 -> 44191 | F138: =ROUND((E138-D138)/7,0) -> 4 | G138: =LEFT(B138,FIND("/",B138)-1) -> 29 | H138: =RIGHT(TRIM(LEFT(B138,FIND("-",B138)-1)),4) -> 2020 | I138: =SUBSTITUTE(MID(SUBSTITUTE("/" & B138&REPT(" ",6),"/",REPT(",",255)),2*255,255),",","") -> 11 | Q138: =Q137+7 -> 42679
...

Sheet Weekly
A2: Weekly deadweight pig prices, EU spec carcase weight and probe
A3: Source: AHDB, EU Commission
A4: Units: Pence per kg, kg, head, mm
A5: Last updated: | C5: =(data_wkly!M1) -> 46234
B7: From | D7: 41734 | E7: <--- Click on cell to select
B8: To | D8: =data_wkly!F1 -> 46228 | E8: <--- Click on cell to select
C10: GB Standard Pig price (SPP) | M10: GB All Pig price (APP) | W10: EU Grade E pig price | AA10: EU Grade S pig price | AF10: GB Deadweight Average Pig price (DAPP) - 2007 to 2014
B11: Week ending | C11: Throughput | D11: EU spec | G11: UK spec | J11: Carcase | M11: Throughput | N11: EU spec | Q11: UK spec | T11: Carcase | W11: EU28 | Y11: (excl. UK) pig price | AA11: EU28 | AC11: (excl. UK) pig price | AF11: EU spec | AI11: UK spec | AL11: Carcase
A12: =SUM(A13:A1276) -> 964 | D12: Price | E12: Change on week | F12: 3 year average | G12: Price | H12: Change on week | I12: 3 year average | J12: Weight (EU) | K12: Probe | N12: Price | O12: Change on week | P12: 3 year average | Q12: Price | R12: Change on week | S12: 3 year average | T12: Weight (EU) | U12: Probe | W12: Price | X12: Change on week | Y12: Price | Z12: Change on week | AA12: Price | AB12: Change on week | AC12: Price | AD12: Change on week | AF12: Price | AG12: Change on week | AH12: 3 year average | AI12: Price | AJ12: Change on week | AK12: 3 year average | AL12: Weight (EU) | AM12: Probe | AN12: =SUM(AN13:AN1276) -> 39
A13: =IF(C13="","",AO13) -> 1 | B13: =D7 -> 41734 | C13: =IFERROR(IF(INDEX(data_wkly!D:D,MATCH($B13,data_wkly!$C:$C,0),1)=0,"",INDEX(data_wkly!D:D,MATCH($B13,data_wkly!$C:$C,0),1)),"") -> 84243 | D13: =IFERROR(IF(INDEX(data_wkly!E:E,MATCH($B13,data_wkly!$C:$C,0),1)=0,"",INDEX(data_wkly!E:E,MATCH($B13,data_wkly!$C:$C,0),1)),"") -> 162.93 | E13: =IF(C13="","",IFERROR(INDEX(data_wkly!F:F,MATCH($B13,data_wkly!$C:$C,0),1),"")) -> na | F13: =IF(E13="","",IFERROR(IF(INDEX(data_wkly!G:G,MATCH($B13,data_wkly!$C:$C,0),1)=0,"",INDEX(data_wkly!G:G,MATCH($B13,data_wkly!$C:$C,0),1)),"")) | G13: =IFERROR(IF(INDEX(data_wkly!H:H,MATCH($B13,data_wkly!$C:$C,0),1)=0,"",INDEX(data_wkly!H:H,MATCH($B13,data_wkly!$C:$C,0),1)),"") -> 159.99 | H13: =IF(C13="","",IFERROR(INDEX(data_wkly!I:I,MATCH($B13,data_wkly!$C:$C,0),1),"")) -> na | I13: =IF(H13="","",IFERROR(IF(INDEX(data_wkly!J:J,MATCH($B13,data_wkly!$C:$C,0),1)=0,"",INDEX(data_wkly!J:J,MATCH($B13,data_wkly!$C:$C,0),1)),"")) | J13: =IFERROR(IF(INDEX(data_wkly!K:K,MATCH($B13,data_wkly!$C:$C,0),1)=0,"",INDEX(data_wkly!K:K,MATCH($B13,data_wkly!$C:$C,0),1)),"") -> 81.15 | K13: =IFERROR(IF(INDEX(data_wkly!L:L,MATCH($B13,data_wkly!$C:$C,0),1)=0,"",INDEX(data_wkly!L:L,MATCH($B13,data_wkly!$C:$C,0),1)),"") -> 11.1 | M13: =IFERROR(IF(INDEX(data_wkly!M:M,MATCH($B13,data_wkly!$C:$C,0),1)=0,"",INDEX(data_wkly!M:M,MATCH($B13,data_wkly!$C:$C,0),1)),"") -> 69305 | N13: =IFERROR(IF(INDEX(data_wkly!N:N,MATCH($B13,data_wkly!$C:$C,0),1)=0,"",INDEX(data_wkly!N:N,MATCH($B13,data_wkly!$C:$C,0),1)),"") -> 164.94 | O13: =IF(M13="","",IFERROR(INDEX(data_wkly!O:O,MATCH($B13,data_wkly!$C:$C,0),1),"")) -> na | P13: =IF(M13="","",IFERROR(IF(INDEX(data_wkly!P:P,MATCH($B13,data_wkly!$C:$C,0),1)=0,"",INDEX(data_wkly!P:P,MATCH($B13,data_wkly!$C:$C,0),1)),"")) | Q13: =IFERROR(IF(INDEX(data_wkly!Q:Q,MATCH($B13,data_wkly!$C:$C,0),1)=0,"",INDEX(data_wkly!Q:Q,MATCH($B13,data_wkly!$C:$C,0),1)),"") -> 161.98 | R13: =IF(M13="","",IFERROR(INDEX(data_wkly!R:R,MATCH($B13,data_wkly!$C:$C,0),1),"")) -> na | S13: =IF(M13="","",IFERROR(IF(INDEX(data_wkly!S:S,MATCH($B13,data_wkly!$C:$C,0),1)=0,"",INDEX(data_wkly!S:S,MATCH($B13,data_wkly!$C:$C,0),1)),"")) | T13: =IFERROR(IF(INDEX(data_wkly!T:T,MATCH($B13,data_wkly!$C:$C,0),1)=0,"",INDEX(data_wkly!T:T,MATCH($B13,data_wkly!$C:$C,0),1)),"") -> 80.54 | U13: =IFERROR(IF(INDEX(data_wkly!U:U,MATCH($B13,data_wkly!$C:$C,0),1)=0,"",INDEX(data_wkly!U:U,MATCH($B13,data_wkly!$C:$C,0),1)),"") -> 11.1 | V13: =IF(M13="","",AO13) -> 1 | W13: =IFERROR(IF(INDEX(data_wkly!W:W,MATCH($B13,data_wkly!$C:$C,0),1)=0,"",INDEX(data_wkly!W:W,MATCH($B13,data_wkly!$C:$C,0),1)),"") -> 131.8234 | X13: =IFERROR(IF(INDEX(data_wkly!X:X,MATCH($B13,data_wkly!$C:$C,0),1)=0,"",INDEX(data_wkly!X:X,MATCH($B13,data_wkly!$C:$C,0),1)),"") -> na | Y13: =IFERROR(IF(INDEX(data_wkly!Y:Y,MATCH($B13,data_wkly!$C:$C,0),1)=0,"",INDEX(data_wkly!Y:Y,MATCH($B13,data_wkly!$C:$C,0),1)),"") -> 132.38531 | Z13: =IFERROR(IF(INDEX(data_wkly!Z:Z,MATCH($B13,data_wkly!$C:$C,0),1)=0,"",INDEX(data_wkly!Z:Z,MATCH($B13,data_wkly!$C:$C,0),1)),"") -> na | AA13: =IFERROR(IF(INDEX(data_wkly!AA:AA,MATCH($B13,data_wkly!$C:$C,0),1)=0,"",INDEX(data_wkly!AA:AA,MATCH($B13,data_wkly!$C:$C,0),1)),"") -> 134.11 | AB13: =IFERROR(IF(INDEX(data_wkly!AB:AB,MATCH($B13,data_wkly!$C:$C,0),1)=0,"",INDEX(data_wkly!AB:AB,MATCH($B13,data_wkly!$C:$C,0),1)),"") -> 0.43 | AC13: =IFERROR(IF(INDEX(data_wkly!AC:AC,MATCH($B13,data_wkly!$C:$C,0),1)=0,"",INDEX(data_wkly!AC:AC,MATCH($B13,data_wkly!$C:$C,0),1)),"") -> 133.1 | AD13: =IFERROR(IF(INDEX(data_wkly!AD:AD,MATCH($B13,data_wkly!$C:$C,0),1)=0,"",INDEX(data_wkly!AD:AD,MATCH($B13,data_wkly!$C:$C,0),1)),"") -> 0.78 | AE13: =IF(W13="","",AO13) -> 1 | AF13: =IFERROR(IF(INDEX(data_wkly!AF:AF,MATCH($B13,data_wkly!$C:$C,0),1)=0,"",INDEX(data_wkly!AF:AF,MATCH($B13,data_wkly!$C:$C,0),1)),"") -> 163.07 | AG13: =IFERROR(IF(AF13="","",INDEX(data_wkly!AG:AG,MATCH($B13,data_wkly!$C:$C,0),1)),"") -> 0.23 | AH13: =IFERROR(IF(INDEX(data_wkly!AH:AH,MATCH($B13,data_wkly!$C:$C,0),1)=0,"",INDEX(data_wkly!AH:AH,MATCH($B13,data_wkly!$C:$C,0),1)),"") -> 146.89667 | AI13: =IFERROR(IF(INDEX(data_wkly!AI:AI,MATCH($B13,data_wkly!$C:$C,0),1)=0,"",INDEX(data_wkly!AI:AI,MATCH($B13,data_wkly!$C:$C,0),1)),"") -> 160.12 | AJ13: =IFERROR(IF(AI13="","",INDEX(data_wkly!AJ:AJ,MATCH($B13,data_wkly!$C:$C,0),1)),"") -> 0.22 | AK13: =IFERROR(IF(INDEX(data_wkly!AK:AK,MATCH($B13,data_wkly!$C:$C,0),1)=0,"",INDEX(data_wkly!AK:AK,MATCH($B13,data_wkly!$C:$C,0),1)),"") -> 144.25333 | AL13: =IFERROR(IF(INDEX(data_wkly!AL:AL,MATCH($B13,data_wkly!$C:$C,0),1)=0,"",INDEX(data_wkly!AL:AL,MATCH($B13,data_wkly!$C:$C,0),1)),"") -> 80.35 | AM13: =IFERROR(IF(INDEX(data_wkly!AM:AM,MATCH($B13,data_wkly!$C:$C,0),1)=0,"",INDEX(data_wkly!AM:AM,MATCH($B13,data_wkly!$C:$C,0),1)),"") -> 11.1 | AN13: =IF(AF13="","",AO13) -> 1 | AO13: 1
A14: =IF(C14="","",AO14) -> 2 | B14: =IFERROR(IF(B13+7<=$D$8,B13+7,""),"") -> 41741 | C14: =IFERROR(IF(INDEX(data_wkly!D:D,MATCH($B14,data_wkly!$C:$C,0),1)=0,"",INDEX(data_wkly!D:D,MATCH($B14,data_wkly!$C:$C,0),1)),"") -> 84107 | D14: =IFERROR(IF(INDEX(data_wkly!E:E,MATCH($B14,data_wkly!$C:$C,0),1)=0,"",INDEX(data_wkly!E:E,MATCH($B14,data_wkly!$C:$C,0),1)),"") -> 163.17 | E14: =IF(C14="","",IFERROR(INDEX(data_wkly!F:F,MATCH($B14,data_wkly!$C:$C,0),1),"")) -> 0.24 | F14: =IF(E14="","",IFERROR(IF(INDEX(data_wkly!G:G,MATCH($B14,data_wkly!$C:$C,0),1)=0,"",INDEX(data_wkly!G:G,MATCH($B14,data_wkly!$C:$C,0),1)),"")) | G14: =IFERROR(IF(INDEX(data_wkly!H:H,MATCH($B14,data_wkly!$C:$C,0),1)=0,"",INDEX(data_wkly!H:H,MATCH($B14,data_wkly!$C:$C,0),1)),"") -> 160.22 | H14: =IF(C14="","",IFERROR(INDEX(data_wkly!I:I,MATCH($B14,data_wkly!$C:$C,0),1),"")) -> 0.23 | I14: =IF(H14="","",IFERROR(IF(INDEX(data_wkly!J:J,MATCH($B14,data_wkly!$C:$C,0),1)=0,"",INDEX(data_wkly!J:J,MATCH($B14,data_wkly!$C:$C,0),1)),"")) | J14: =IFERROR(IF(INDEX(data_wkly!K:K,MATCH($B14,data_wkly!$C:$C,0),1)=0,"",INDEX(data_wkly!K:K,MATCH($B14,data_wkly!$C:$C,0),1)),"") -> 81.06 | K14: =IFERROR(IF(INDEX(data_wkly!L:L,MATCH($B14,data_wkly!$C:$C,0),1)=0,"",INDEX(data_wkly!L:L,MATCH($B14,data_wkly!$C:$C,0),1)),"") -> 11 | M14: =IFERROR(IF(INDEX(data_wkly!M:M,MATCH($B14,data_wkly!$C:$C,0),1)=0,"",INDEX(data_wkly!M:M,MATCH($B14,data_wkly!$C:$C,0),1)),"") -> 73548 | N14: =IFERROR(IF(INDEX(data_wkly!N:N,MATCH($B14,data_wkly!$C:$C,0),1)=0,"",INDEX(data_wkly!N:N,MATCH($B14,data_wkly!$C:$C,0),1)),"") -> 165.07 | O14: =IF(M14="","",IFERROR(INDEX(data_wkly!O:O,MATCH($B14,data_wkly!$C:$C,0),1),"")) -> 0.13 | P14: =IF(M14="","",IFERROR(IF(INDEX(data_wkly!P:P,MATCH($B14,data_wkly!$C:$C,0),1)=0,"",INDEX(data_wkly!P:P,MATCH($B14,data_wkly!$C:$C,0),1)),"")) | Q14: =IFERROR(IF(INDEX(data_wkly!Q:Q,MATCH($B14,data_wkly!$C:$C,0),1)=0,"",INDEX(data_wkly!Q:Q,MATCH($B14,data_wkly!$C:$C,0),1)),"") -> 162.09 | R14: =IF(M14="","",IFERROR(INDEX(data_wkly!R:R,MATCH($B14,data_wkly!$C:$C,0),1),"")) -> 0.11 | S14: =IF(M14="","",IFERROR(IF(INDEX(data_wkly!S:S,MATCH($B14,data_wkly!$C:$C,0),1)=0,"",INDEX(data_wkly!S:S,MATCH($B14,data_wkly!$C:$C,0),1)),"")) | T14: =IFERROR(IF(INDEX(data_wkly!T:T,MATCH($B14,data_wkly!$C:$C,0),1)=0,"",INDEX(data_wkly!T:T,MATCH($B14,data_wkly!$C:$C,0),1)),"") -> 80.57 | U14: =IFERROR(IF(INDEX(data_wkly!U:U,MATCH($B14,data_wkly!$C:$C,0),1)=0,"",INDEX(data_wkly!U:U,MATCH($B14,data_wkly!$C:$C,0),1)),"") -> 11.1 | V14: =IF(M14="","",AO14) -> 2 | W14: =IFERROR(IF(INDEX(data_wkly!W:W,MATCH($B14,data_wkly!$C:$C,0),1)=0,"",INDEX(data_wkly!W:W,MATCH($B14,data_wkly!$C:$C,0),1)),"") -> 133.4518 | X14: =IFERROR(IF(INDEX(data_wkly!X:X,MATCH($B14,data_wkly!$C:$C,0),1)=0,"",INDEX(data_wkly!X:X,MATCH($B14,data_wkly!$C:$C,0),1)),"") -> 1.6284456 | Y14: =IFERROR(IF(INDEX(data_wkly!Y:Y,MATCH($B14,data_wkly!$C:$C,0),1)=0,"",INDEX(data_wkly!Y:Y,MATCH($B14,data_wkly!$C:$C,0),1)),"") -> 134.02 | Z14: =IFERROR(IF(INDEX(data_wkly!Z:Z,MATCH($B14,data_wkly!$C:$C,0),1)=0,"",INDEX(data_wkly!Z:Z,MATCH($B14,data_wkly!$C:$C,0),1)),"") -> 1.6346919 | AA14: =IFERROR(IF(INDEX(data_wkly!AA:AA,MATCH($B14,data_wkly!$C:$C,0),1)=0,"",INDEX(data_wkly!AA:AA,MATCH($B14,data_wkly!$C:$C,0),1)),"") -> 136.46 | AB14: =IFERROR(IF(INDEX(data_wkly!AB:AB,MATCH($B14,data_wkly!$C:$C,0),1)=0,"",INDEX(data_wkly!AB:AB,MATCH($B14,data_wkly!$C:$C,0),1)),"") -> 2.35 | AC14: =IFERROR(IF(INDEX(data_wkly!AC:AC,MATCH($B14,data_wkly!$C:$C,0),1)=0,"",INDEX(data_wkly!AC:AC,MATCH($B14,data_wkly!$C:$C,0),1)),"") -> 135.79 | AD14: =IFERROR(IF(INDEX(data_wkly!AD:AD,MATCH($B14,data_wkly!$C:$C,0),1)=0,"",INDEX(data_wkly!AD:AD,MATCH($B14,data_wkly!$C:$C,0),1)),"") -> 2.69 | AE14: =IF(W14="","",AO14) -> 2 | AF14: =IFERROR(IF(INDEX(data_wkly!AF:AF,MATCH($B14,data_wkly!$C:$C,0),1)=0,"",INDEX(data_wkly!AF:AF,MATCH($B14,data_wkly!$C:$C,0),1)),"") -> 163.28 | AG14: =IFERROR(IF(AF14="","",INDEX(data_wkly!AG:AG,MATCH($B14,data_wkly!$C:$C,0),1)),"") -> 0.21 | AH14: =IFERROR(IF(INDEX(data_wkly!AH:AH,MATCH($B14,data_wkly!$C:$C,0),1)=0,"",INDEX(data_wkly!AH:AH,MATCH($B14,data_wkly!$C:$C,0),1)),"") -> 147.76 | AI14: =IFERROR(IF(INDEX(data_wkly!AI:AI,MATCH($B14,data_wkly!$C:$C,0),1)=0,"",INDEX(data_wkly!AI:AI,MATCH($B14,data_wkly!$C:$C,0),1)),"") -> 160.33 | AJ14: =IFERROR(IF(AI14="","",INDEX(data_wkly!AJ:AJ,MATCH($B14,data_wkly!$C:$C,0),1)),"") -> 0.21 | AK14: =IFERROR(IF(INDEX(data_wkly!AK:AK,MATCH($B14,data_wkly!$C:$C,0),1)=0,"",INDEX(data_wkly!AK:AK,MATCH($B14,data_wkly!$C:$C,0),1)),"") -> 145 | AL14: =IFERROR(IF(INDEX(data_wkly!AL:AL,MATCH($B14,data_wkly!$C:$C,0),1)=0,"",INDEX(data_wkly!AL:AL,MATCH($B14,data_wkly!$C:$C,0),1)),"") -> 80.31 | AM14: =IFERROR(IF(INDEX(data_wkly!AM:AM,MATCH($B14,data_wkly!$C:$C,0),1)=0,"",INDEX(data_wkly!AM:AM,MATCH($B14,data_wkly!$C:$C,0),1)),"") -> 10.9 | AN14: =IF(AF14="","",AO14) -> 2 | AO14: 2
A15: =IF(C15="","",AO15) -> 1 | B15: =IFERROR(IF(B14+7<=$D$8,B14+7,""),"") -> 41748 | C15: =IFERROR(IF(INDEX(data_wkly!D:D,MATCH($B15,data_wkly!$C:$C,0),1)=0,"",INDEX(data_wkly!D:D,MATCH($B15,data_wkly!$C:$C,0),1)),"") -> 79999 | D15: =IFERROR(IF(INDEX(data_wkly!E:E,MATCH($B15,data_wkly!$C:$C,0),1)=0,"",INDEX(data_wkly!E:E,MATCH($B15,data_wkly!$C:$C,0),1)),"") -> 163.28 | E15: =IF(C15="","",IFERROR(INDEX(data_wkly!F:F,MATCH($B15,data_wkly!$C:$C,0),1),"")) -> 0.11 | F15: =IF(E15="","",IFERROR(IF(INDEX(data_wkly!G:G,MATCH($B15,data_wkly!$C:$C,0),1)=0,"",INDEX(data_wkly!G:G,MATCH($B15,data_wkly!$C:$C,0),1)),"")) | G15: =IFERROR(IF(INDEX(data_wkly!H:H,MATCH($B15,data_wkly!$C:$C,0),1)=0,"",INDEX(data_wkly!H:H,MATCH($B15,data_wkly!$C:$C,0),1)),"") -> 160.33 | H15: =IF(C15="","",IFERROR(INDEX(data_wkly!I:I,MATCH($B15,data_wkly!$C:$C,0),1),"")) -> 0.11 | I15: =IF(H15="","",IFERROR(IF(INDEX(data_wkly!J:J,MATCH($B15,data_wkly!$C:$C,0),1)=0,"",INDEX(data_wkly!J:J,MATCH($B15,data_wkly!$C:$C,0),1)),"")) | J15: =IFERROR(IF(INDEX(data_wkly!K:K,MATCH($B15,data_wkly!$C:$C,0),1)=0,"",INDEX(data_wkly!K:K,MATCH($B15,data_wkly!$C:$C,0),1)),"") -> 80.8 | K15: =IFERROR(IF(INDEX(data_wkly!L:L,MATCH($B15,data_wkly!$C:$C,0),1)=0,"",INDEX(data_wkly!L:L,MATCH($B15,data_wkly!$C:$C,0),1)),"") -> 11 | M15: =IFERROR(IF(INDEX(data_wkly!M:M,MATCH($B15,data_wkly!$C:$C,0),1)=0,"",INDEX(data_wkly!M:M,MATCH($B15,data_wkly!$C:$C,0),1)),"") -> 68439 | N15: =IFERROR(IF(INDEX(data_wkly!N:N,MATCH($B15,data_wkly!$C:$C,0),1)=0,"",INDEX(data_wkly!N:N,MATCH($B15,data_wkly!$C:$C,0),1)),"") -> 164.89 | O15: =IF(M15="","",IFERROR(INDEX(data_wkly!O:O,MATCH($B15,data_wkly!$C:$C,0),1),"")) -> -0.18 | P15: =IF(M15="","",IFERROR(IF(INDEX(data_wkly!P:P,MATCH($B15,data_wkly!$C:$C,0),1)=0,"",INDEX(data_wkly!P:P,MATCH($B15,data_wkly!$C:$C,0),1)),"")) | Q15: =IFERROR(IF(INDEX(data_wkly!Q:Q,MATCH($B15,data_wkly!$C:$C,0),1)=0,"",INDEX(data_wkly!Q:Q,MATCH($B15,data_wkly!$C:$C,0),1)),"") -> 161.92 | R15: =IF(M15="","",IFERROR(INDEX(data_wkly!R:R,MATCH($B15,data_wkly!$C:$C,0),1),"")) -> -0.17 | S15: =IF(M15="","",IFERROR(IF(INDEX(data_wkly!S:S,MATCH($B15,data_wkly!$C:$C,0),1)=0,"",INDEX(data_wkly!S:S,MATCH($B15,data_wkly!$C:$C,0),1)),"")) | T15: =IFERROR(IF(INDEX(data_wkly!T:T,MATCH($B15,data_wkly!$C:$C,0),1)=0,"",INDEX(data_wkly!T:T,MATCH($B15,data_wkly!$C:$C,0),1)),"") -> 80.28 | U15: =IFERROR(IF(INDEX(data_wkly!U:U,MATCH($B15,data_wkly!$C:$C,0),1)=0,"",INDEX(data_wkly!U:U,MATCH($B15,data_wkly!$C:$C,0),1)),"") -> 11.1 | V15: =IF(M15="","",AO15) -> 1 | W15: =IFERROR(IF(INDEX(data_wkly!W:W,MATCH($B15,data_wkly!$C:$C,0),1)=0,"",INDEX(data_wkly!W:W,MATCH($B15,data_wkly!$C:$C,0),1)),"") -> 134.0944 | X15: =IFERROR(IF(INDEX(data_wkly!X:X,MATCH($B15,data_wkly!$C:$C,0),1)=0,"",INDEX(data_wkly!X:X,MATCH($B15,data_wkly!$C:$C,0),1)),"") -> 0.64251751 | Y15: =IFERROR(IF(INDEX(data_wkly!Y:Y,MATCH($B15,data_wkly!$C:$C,0),1)=0,"",INDEX(data_wkly!Y:Y,MATCH($B15,data_wkly!$C:$C,0),1)),"") -> 134.52 | Z15: =IFERROR(IF(INDEX(data_wkly!Z:Z,MATCH($B15,data_wkly!$C:$C,0),1)=0,"",INDEX(data_wkly!Z:Z,MATCH($B15,data_wkly!$C:$C,0),1)),"") -> 0.5 | AA15: =IFERROR(IF(INDEX(data_wkly!AA:AA,MATCH($B15,data_wkly!$C:$C,0),1)=0,"",INDEX(data_wkly!AA:AA,MATCH($B15,data_wkly!$C:$C,0),1)),"") -> 137.66 | AB15: =IFERROR(IF(INDEX(data_wkly!AB:AB,MATCH($B15,data_wkly!$C:$C,0),1)=0,"",INDEX(data_wkly!AB:AB,MATCH($B15,data_wkly!$C:$C,0),1)),"") -> 1.2 | AC15: =IFERROR(IF(INDEX(data_wkly!AC:AC,MATCH($B15,data_wkly!$C:$C,0),1)=0,"",INDEX(data_wkly!AC:AC,MATCH($B15,data_wkly!$C:$C,0),1)),"") -> 136.7 | AD15: =IFERROR(IF(INDEX(data_wkly!AD:AD,MATCH($B15,data_wkly!$C:$C,0),1)=0,"",INDEX(data_wkly!AD:AD,MATCH($B15,data_wkly!$C:$C,0),1)),"") -> 0.91 | AE15: =IF(W15="","",AO15) -> 1 | AF15: =IFERROR(IF(INDEX(data_wkly!AF:AF,MATCH($B15,data_wkly!$C:$C,0),1)=0,"",INDEX(data_wkly!AF:AF,MATCH($B15,data_wkly!$C:$C,0),1)),"") -> 163.71 | AG15: =IFERROR(IF(AF15="","",INDEX(data_wkly!AG:AG,MATCH($B15,data_wkly!$C:$C,0),1)),"") -> 0.43 | AH15: =IFERROR(IF(INDEX(data_wkly!AH:AH,MATCH($B15,data_wkly!$C:$C,0),1)=0,"",INDEX(data_wkly!AH:AH,MATCH($B15,data_wkly!$C:$C,0),1)),"") -> 149.30667 | AI15: =IFERROR(IF(INDEX(data_wkly!AI:AI,MATCH($B15,data_wkly!$C:$C,0),1)=0,"",INDEX(data_wkly!AI:AI,MATCH($B15,data_wkly!$C:$C,0),1)),"") -> 160.75 | AJ15: =IFERROR(IF(AI15="","",INDEX(data_wkly!AJ:AJ,MATCH($B15,data_wkly!$C:$C,0),1)),"") -> 0.42 | AK15: =IFERROR(IF(INDEX(data_wkly!AK:AK,MATCH($B15,data_wkly!$C:$C,0),1)=0,"",INDEX(data_wkly!AK:AK,MATCH($B15,data_wkly!$C:$C,0),1)),"") -> 146.60667 | AL15: =IFERROR(IF(INDEX(data_wkly!AL:AL,MATCH($B15,data_wkly!$C:$C,0),1)=0,"",INDEX(data_wkly!AL:AL,MATCH($B15,data_wkly!$C:$C,0),1)),"") -> 79.88 | AM15: =IFERROR(IF(INDEX(data_wkly!AM:AM,MATCH($B15,data_wkly!$C:$C,0),1)=0,"",INDEX(data_wkly!AM:AM,MATCH($B15,data_wkly!$C:$C,0),1)),"") -> 10.9 | AN15: =IF(AF15="","",AO15) -> 1 | AO15: =AO13 -> 1
A16: =IF(C16="","",AO16) -> 2 | B16: =IFERROR(IF(B15+7<=$D$8,B15+7,""),"") -> 41755 | C16: =IFERROR(IF(INDEX(data_wkly!D:D,MATCH($B16,data_wkly!$C:$C,0),1)=0,"",INDEX(data_wkly!D:D,MATCH($B16,data_wkly!$C:$C,0),1)),"") -> 80888 | D16: =IFERROR(IF(INDEX(data_wkly!E:E,MATCH($B16,data_wkly!$C:$C,0),1)=0,"",INDEX(data_wkly!E:E,MATCH($B16,data_wkly!$C:$C,0),1)),"") -> 163.21 | E16: =IF(C16="","",IFERROR(INDEX(data_wkly!F:F,MATCH($B16,data_wkly!$C:$C,0),1),"")) -> -0.07 | F16: =IF(E16="","",IFERROR(IF(INDEX(data_wkly!G:G,MATCH($B16,data_wkly!$C:$C,0),1)=0,"",INDEX(data_wkly!G:G,MATCH($B16,data_wkly!$C:$C,0),1)),"")) | G16: =IFERROR(IF(INDEX(data_wkly!H:H,MATCH($B16,data_wkly!$C:$C,0),1)=0,"",INDEX(data_wkly!H:H,MATCH($B16,data_wkly!$C:$C,0),1)),"") -> 160.27 | H16: =IF(C16="","",IFERROR(INDEX(data_wkly!I:I,MATCH($B16,data_wkly!$C:$C,0),1),"")) -> -0.06 | I16: =IF(H16="","",IFERROR(IF(INDEX(data_wkly!J:J,MATCH($B16,data_wkly!$C:$C,0),1)=0,"",INDEX(data_wkly!J:J,MATCH($B16,data_wkly!$C:$C,0),1)),"")) | J16: =IFERROR(IF(INDEX(data_wkly!K:K,MATCH($B16,data_wkly!$C:$C,0),1)=0,"",INDEX(data_wkly!K:K,MATCH($B16,data_wkly!$C:$C,0),1)),"") -> 80.92 | K16: =IFERROR(IF(INDEX(data_wkly!L:L,MATCH($B16,data_wkly!$C:$C,0),1)=0,"",INDEX(data_wkly!L:L,MATCH($B16,data_wkly!$C:$C,0),1)),"") -> 10.9 | M16: =IFERROR(IF(INDEX(data_wkly!M:M,MATCH($B16,data_wkly!$C:$C,0),1)=0,"",INDEX(data_wkly!M:M,MATCH($B16,data_wkly!$C:$C,0),1)),"") -> 67759 | N16: =IFERROR(IF(INDEX(data_wkly!N:N,MATCH($B16,data_wkly!$C:$C,0),1)=0,"",INDEX(data_wkly!N:N,MATCH($B16,data_wkly!$C:$C,0),1)),"") -> 165.57 | O16: =IF(M16="","",IFERROR(INDEX(data_wkly!O:O,MATCH($B16,data_wkly!$C:$C,0),1),"")) -> 0.68 | P16: =IF(M16="","",IFERROR(IF(INDEX(data_wkly!P:P,MATCH($B16,data_wkly!$C:$C,0),1)=0,"",INDEX(data_wkly!P:P,MATCH($B16,data_wkly!$C:$C,0),1)),"")) | Q16: =IFERROR(IF(INDEX(data_wkly!Q:Q,MATCH($B16,data_wkly!$C:$C,0),1)=0,"",INDEX(data_wkly!Q:Q,MATCH($B16,data_wkly!$C:$C,0),1)),"") -> 162.59 | R16: =IF(M16="","",IFERROR(INDEX(data_wkly!R:R,MATCH($B16,data_wkly!$C:$C,0),1),"")) -> 0.67 | S16: =IF(M16="","",IFERROR(IF(INDEX(data_wkly!S:S,MATCH($B16,data_wkly!$C:$C,0),1)=0,"",INDEX(data_wkly!S:S,MATCH($B16,data_wkly!$C:$C,0),1)),"")) | T16: =IFERROR(IF(INDEX(data_wkly!T:T,MATCH($B16,data_wkly!$C:$C,0),1)=0,"",INDEX(data_wkly!T:T,MATCH($B16,data_wkly!$C:$C,0),1)),"") -> 80.34 | U16: =IFERROR(IF(INDEX(data_wkly!U:U,MATCH($B16,data_wkly!$C:$C,0),1)=0,"",INDEX(data_wkly!U:U,MATCH($B16,data_wkly!$C:$C,0),1)),"") -> 11 | V16: =IF(M16="","",AO16) -> 2 | W16: =IFERROR(IF(INDEX(data_wkly!W:W,MATCH($B16,data_wkly!$C:$C,0),1)=0,"",INDEX(data_wkly!W:W,MATCH($B16,data_wkly!$C:$C,0),1)),"") -> 133.2527 | X16: =IFERROR(IF(INDEX(data_wkly!X:X,MATCH($B16,data_wkly!$C:$C,0),1)=0,"",INDEX(data_wkly!X:X,MATCH($B16,data_wkly!$C:$C,0),1)),"") -> -0.84161883 | Y16: =IFERROR(IF(INDEX(data_wkly!Y:Y,MATCH($B16,data_wkly!$C:$C,0),1)=0,"",INDEX(data_wkly!Y:Y,MATCH($B16,data_wkly!$C:$C,0),1)),"") -> 133.63 | Z16: =IFERROR(IF(INDEX(data_wkly!Z:Z,MATCH($B16,data_wkly!$C:$C,0),1)=0,"",INDEX(data_wkly!Z:Z,MATCH($B16,data_wkly!$C:$C,0),1)),"") -> -0.89 | AA16: =IFERROR(IF(INDEX(data_wkly!AA:AA,MATCH($B16,data_wkly!$C:$C,0),1)=0,"",INDEX(data_wkly!AA:AA,MATCH($B16,data_wkly!$C:$C,0),1)),"") -> 136.96 | AB16: =IFERROR(IF(INDEX(data_wkly!AB:AB,MATCH($B16,data_wkly!$C:$C,0),1)=0,"",INDEX(data_wkly!AB:AB,MATCH($B16,data_wkly!$C:$C,0),1)),"") -> -0.7 | AC16: =IFERROR(IF(INDEX(data_wkly!AC:AC,MATCH($B16,data_wkly!$C:$C,0),1)=0,"",INDEX(data_wkly!AC:AC,MATCH($B16,data_wkly!$C:$C,0),1)),"") -> 135.74 | AD16: =IFERROR(IF(INDEX(data_wkly!AD:AD,MATCH($B16,data_wkly!$C:$C,0),1)=0,"",INDEX(data_wkly!AD:AD,MATCH($B16,data_wkly!$C:$C,0),1)),"") -> -0.96 | AE16: =IF(W16="","",AO16) -> 2 | AF16: =IFERROR(IF(INDEX(data_wkly!AF:AF,MATCH($B16,data_wkly!$C:$C,0),1)=0,"",INDEX(data_wkly!AF:AF,MATCH($B16,data_wkly!$C:$C,0),1)),"") -> 163.42 | AG16: =IFERROR(IF(AF16="","",INDEX(data_wkly!AG:AG,MATCH($B16,data_wkly!$C:$C,0),1)),"") -> -0.29 | AH16: =IFERROR(IF(INDEX(data_wkly!AH:AH,MATCH($B16,data_wkly!$C:$C,0),1)=0,"",INDEX(data_wkly!AH:AH,MATCH($B16,data_wkly!$C:$C,0),1)),"") -> 149.95333 | AI16: =IFERROR(IF(INDEX(data_wkly!AI:AI,MATCH($B16,data_wkly!$C:$C,0),1)=0,"",INDEX(data_wkly!AI:AI,MATCH($B16,data_wkly!$C:$C,0),1)),"") -> 160.46 | AJ16: =IFERROR(IF(AI16="","",INDEX(data_wkly!AJ:AJ,MATCH($B16,data_wkly!$C:$C,0),1)),"") -> -0.29 | AK16: =IFERROR(IF(INDEX(data_wkly!AK:AK,MATCH($B16,data_wkly!$C:$C,0),1)=0,"",INDEX(data_wkly!AK:AK,MATCH($B16,data_wkly!$C:$C,0),1)),"") -> 147.25333 | AL16: =IFERROR(IF(INDEX(data_wkly!AL:AL,MATCH($B16,data_wkly!$C:$C,0),1)=0,"",INDEX(data_wkly!AL:AL,MATCH($B16,data_wkly!$C:$C,0),1)),"") -> 80.03 | AM16: =IFERROR(IF(INDEX(data_wkly!AM:AM,MATCH($B16,data_wkly!$C:$C,0),1)=0,"",INDEX(data_wkly!AM:AM,MATCH($B16,data_wkly!$C:$C,0),1)),"") -> 10.8 | AN16: =IF(AF16="","",AO16) -> 2 | AO16: =AO14 -> 2
A17: =IF(C17="","",AO17) -> 1 | B17: =IFERROR(IF(B16+7<=$D$8,B16+7,""),"") -> 41762 | C17: =IFERROR(IF(INDEX(data_wkly!D:D,MATCH($B17,data_wkly!$C:$C,0),1)=0,"",INDEX(data_wkly!D:D,MATCH($B17,data_wkly!$C:$C,0),1)),"") -> 79838 | D17: =IFERROR(IF(INDEX(data_wkly!E:E,MATCH($B17,data_wkly!$C:$C,0),1)=0,"",INDEX(data_wkly!E:E,MATCH($B17,data_wkly!$C:$C,0),1)),"") -> 163.74 | E17: =IF(C17="","",IFERROR(INDEX(data_wkly!F:F,MATCH($B17,data_wkly!$C:$C,0),1),"")) -> 0.53 | F17: =IF(E17="","",IFERROR(IF(INDEX(data_wkly!G:G,MATCH($B17,data_wkly!$C:$C,0),1)=0,"",INDEX(data_wkly!G:G,MATCH($B17,data_wkly!$C:$C,0),1)),"")) | G17: =IFERROR(IF(INDEX(data_wkly!H:H,MATCH($B17,data_wkly!$C:$C,0),1)=0,"",INDEX(data_wkly!H:H,MATCH($B17,data_wkly!$C:$C,0),1)),"") -> 160.79 | H17: =IF(C17="","",IFERROR(INDEX(data_wkly!I:I,MATCH($B17,data_wkly!$C:$C,0),1),"")) -> 0.52 | I17: =IF(H17="","",IFERROR(IF(INDEX(data_wkly!J:J,MATCH($B17,data_wkly!$C:$C,0),1)=0,"",INDEX(data_wkly!J:J,MATCH($B17,data_wkly!$C:$C,0),1)),"")) | J17: =IFERROR(IF(INDEX(data_wkly!K:K,MATCH($B17,data_wkly!$C:$C,0),1)=0,"",INDEX(data_wkly!K:K,MATCH($B17,data_wkly!$C:$C,0),1)),"") -> 80.77 | K17: =IFERROR(IF(INDEX(data_wkly!L:L,MATCH($B17,data_wkly!$C:$C,0),1)=0,"",INDEX(data_wkly!L:L,MATCH($B17,data_wkly!$C:$C,0),1)),"") -> 10.9 | M17: =IFERROR(IF(INDEX(data_wkly!M:M,MATCH($B17,data_wkly!$C:$C,0),1)=0,"",INDEX(data_wkly!M:M,MATCH($B17,data_wkly!$C:$C,0),1)),"") -> 70010 | N17: =IFERROR(IF(INDEX(data_wkly!N:N,MATCH($B17,data_wkly!$C:$C,0),1)=0,"",INDEX(data_wkly!N:N,MATCH($B17,data_wkly!$C:$C,0),1)),"") -> 165.77 | O17: =IF(M17="","",IFERROR(INDEX(data_wkly!O:O,MATCH($B17,data_wkly!$C:$C,0),1),"")) -> 0.2 | P17: =IF(M17="","",IFERROR(IF(INDEX(data_wkly!P:P,MATCH($B17,data_wkly!$C:$C,0),1)=0,"",INDEX(data_wkly!P:P,MATCH($B17,data_wkly!$C:$C,0),1)),"")) | Q17: =IFERROR(IF(INDEX(data_wkly!Q:Q,MATCH($B17,data_wkly!$C:$C,0),1)=0,"",INDEX(data_wkly!Q:Q,MATCH($B17,data_wkly!$C:$C,0),1)),"") -> 162.78 | R17: =IF(M17="","",IFERROR(INDEX(data_wkly!R:R,MATCH($B17,data_wkly!$C:$C,0),1),"")) -> 0.19 | S17: =IF(M17="","",IFERROR(IF(INDEX(data_wkly!S:S,MATCH($B17,data_wkly!$C:$C,0),1)=0,"",INDEX(data_wkly!S:S,MATCH($B17,data_wkly!$C:$C,0),1)),"")) | T17: =IFERROR(IF(INDEX(data_wkly!T:T,MATCH($B17,data_wkly!$C:$C,0),1)=0,"",INDEX(data_wkly!T:T,MATCH($B17,data_wkly!$C:$C,0),1)),"") -> 80.44 | U17: =IFERROR(IF(INDEX(data_wkly!U:U,MATCH($B17,data_wkly!$C:$C,0),1)=0,"",INDEX(data_wkly!U:U,MATCH($B17,data_wkly!$C:$C,0),1)),"") -> 10.9 | V17: =IF(M17="","",AO17) -> 1 | W17: =IFERROR(IF(INDEX(data_wkly!W:W,MATCH($B17,data_wkly!$C:$C,0),1)=0,"",INDEX(data_wkly!W:W,MATCH($B17,data_wkly!$C:$C,0),1)),"") -> 134.0977 | X17: =IFERROR(IF(INDEX(data_wkly!X:X,MATCH($B17,data_wkly!$C:$C,0),1)=0,"",INDEX(data_wkly!X:X,MATCH($B17,data_wkly!$C:$C,0),1)),"") -> 0.84495762 | Y17: =IFERROR(IF(INDEX(data_wkly!Y:Y,MATCH($B17,data_wkly!$C:$C,0),1)=0,"",INDEX(data_wkly!Y:Y,MATCH($B17,data_wkly!$C:$C,0),1)),"") -> 134.36 | Z17: =IFERROR(IF(INDEX(data_wkly!Z:Z,MATCH($B17,data_wkly!$C:$C,0),1)=0,"",INDEX(data_wkly!Z:Z,MATCH($B17,data_wkly!$C:$C,0),1)),"") -> 0.73 | AA17: =IFERROR(IF(INDEX(data_wkly!AA:AA,MATCH($B17,data_wkly!$C:$C,0),1)=0,"",INDEX(data_wkly!AA:AA,MATCH($B17,data_wkly!$C:$C,0),1)),"") -> 137.52 | AB17: =IFERROR(IF(INDEX(data_wkly!AB:AB,MATCH($B17,data_wkly!$C:$C,0),1)=0,"",INDEX(data_wkly!AB:AB,MATCH($B17,data_wkly!$C:$C,0),1)),"") -> 0.56 | AC17: =IFERROR(IF(INDEX(data_wkly!AC:AC,MATCH($B17,data_wkly!$C:$C,0),1)=0,"",INDEX(data_wkly!AC:AC,MATCH($B17,data_wkly!$C:$C,0),1)),"") -> 136.25 | AD17: =IFERROR(IF(INDEX(data_wkly!AD:AD,MATCH($B17,data_wkly!$C:$C,0),1)=0,"",INDEX(data_wkly!AD:AD,MATCH($B17,data_wkly!$C:$C,0),1)),"") -> 0.51 | AE17: =IF(W17="","",AO17) -> 1 | AF17: =IFERROR(IF(INDEX(data_wkly!AF:AF,MATCH($B17,data_wkly!$C:$C,0),1)=0,"",INDEX(data_wkly!AF:AF,MATCH($B17,data_wkly!$C:$C,0),1)),"") -> 163.9 | AG17: =IFERROR(IF(AF17="","",INDEX(data_wkly!AG:AG,MATCH($B17,data_wkly!$C:$C,0),1)),"") -> 0.48 | AH17: =IFERROR(IF(INDEX(data_wkly!AH:AH,MATCH($B17,data_wkly!$C:$C,0),1)=0,"",INDEX(data_wkly!AH:AH,MATCH($B17,data_wkly!$C:$C,0),1)),"") -> 151.21333 | AI17: =IFERROR(IF(INDEX(data_wkly!AI:AI,MATCH($B17,data_wkly!$C:$C,0),1)=0,"",INDEX(data_wkly!AI:AI,MATCH($B17,data_wkly!$C:$C,0),1)),"") -> 160.94 | AJ17: =IFERROR(IF(AI17="","",INDEX(data_wkly!AJ:AJ,MATCH($B17,data_wkly!$C:$C,0),1)),"") -> 0.48 | AK17: =IFERROR(IF(INDEX(data_wkly!AK:AK,MATCH($B17,data_wkly!$C:$C,0),1)=0,"",INDEX(data_wkly!AK:AK,MATCH($B17,data_wkly!$C:$C,0),1)),"") -> 148.49667 | AL17: =IFERROR(IF(INDEX(data_wkly!AL:AL,MATCH($B17,data_wkly!$C:$C,0),1)=0,"",INDEX(data_wkly!AL:AL,MATCH($B17,data_wkly!$C:$C,0),1)),"") -> 80.09 | AM17: =IFERROR(IF(INDEX(data_wkly!AM:AM,MATCH($B17,data_wkly!$C:$C,0),1)=0,"",INDEX(data_wkly!AM:AM,MATCH($B17,data_wkly!$C:$C,0),1)),"") -> 10.8 | AN17: =IF(AF17="","",AO17) -> 1 | AO17: =AO15 -> 1
A18: =IF(C18="","",AO18) -> 2 | B18: =IFERROR(IF(B17+7<=$D$8,B17+7,""),"") -> 41769 | C18: =IFERROR(IF(INDEX(data_wkly!D:D,MATCH($B18,data_wkly!$C:$C,0),1)=0,"",INDEX(data_wkly!D:D,MATCH($B18,data_wkly!$C:$C,0),1)),"") -> 81411 | D18: =IFERROR(IF(INDEX(data_wkly!E:E,MATCH($B18,data_wkly!$C:$C,0),1)=0,"",INDEX(data_wkly!E:E,MATCH($B18,data_wkly!$C:$C,0),1)),"") -> 163.75 | E18: =IF(C18="","",IFERROR(INDEX(data_wkly!F:F,MATCH($B18,data_wkly!$C:$C,0),1),"")) -> 0.01 | F18: =IF(E18="","",IFERROR(IF(INDEX(data_wkly!G:G,MATCH($B18,data_wkly!$C:$C,0),1)=0,"",INDEX(data_wkly!G:G,MATCH($B18,data_wkly!$C:$C,0),1)),"")) | G18: =IFERROR(IF(INDEX(data_wkly!H:H,MATCH($B18,data_wkly!$C:$C,0),1)=0,"",INDEX(data_wkly!H:H,MATCH($B18,data_wkly!$C:$C,0),1)),"") -> 160.8 | H18: =IF(C18="","",IFERROR(INDEX(data_wkly!I:I,MATCH($B18,data_wkly!$C:$C,0),1),"")) -> 0.01 | I18: =IF(H18="","",IFERROR(IF(INDEX(data_wkly!J:J,MATCH($B18,data_wkly!$C:$C,0),1)=0,"",INDEX(data_wkly!J:J,MATCH($B18,data_wkly!$C:$C,0),1)),"")) | J18: =IFERROR(IF(INDEX(data_wkly!K:K,MATCH($B18,data_wkly!$C:$C,0),1)=0,"",INDEX(data_wkly!K:K,MATCH($B18,data_wkly!$C:$C,0),1)),"") -> 81.04 | K18: =IFERROR(IF(INDEX(data_wkly!L:L,MATCH($B18,data_wkly!$C:$C,0),1)=0,"",INDEX(data_wkly!L:L,MATCH($B18,data_wkly!$C:$C,0),1)),"") -> 10.9 | M18: =IFERROR(IF(INDEX(data_wkly!M:M,MATCH($B18,data_wkly!$C:$C,0),1)=0,"",INDEX(data_wkly!M:M,MATCH($B18,data_wkly!$C:$C,0),1)),"") -> 70233 | N18: =IFERROR(IF(INDEX(data_wkly!N:N,MATCH($B18,data_wkly!$C:$C,0),1)=0,"",INDEX(data_wkly!N:N,MATCH($B18,data_wkly!$C:$C,0),1)),"") -> 165.82 | O18: =IF(M18="","",IFERROR(INDEX(data_wkly!O:O,MATCH($B18,data_wkly!$C:$C,0),1),"")) -> 0.05 | P18: =IF(M18="","",IFERROR(IF(INDEX(data_wkly!P:P,MATCH($B18,data_wkly!$C:$C,0),1)=0,"",INDEX(data_wkly!P:P,MATCH($B18,data_wkly!$C:$C,0),1)),"")) | Q18: =IFERROR(IF(INDEX(data_wkly!Q:Q,MATCH($B18,data_wkly!$C:$C,0),1)=0,"",INDEX(data_wkly!Q:Q,MATCH($B18,data_wkly!$C:$C,0),1)),"") -> 162.83 | R18: =IF(M18="","",IFERROR(INDEX(data_wkly!R:R,MATCH($B18,data_wkly!$C:$C,0),1),"")) -> 0.05 | S18: =IF(M18="","",IFERROR(IF(INDEX(data_wkly!S:S,MATCH($B18,data_wkly!$C:$C,0),1)=0,"",INDEX(data_wkly!S:S,MATCH($B18,data_wkly!$C:$C,0),1)),"")) | T18: =IFERROR(IF(INDEX(data_wkly!T:T,MATCH($B18,data_wkly!$C:$C,0),1)=0,"",INDEX(data_wkly!T:T,MATCH($B18,data_wkly!$C:$C,0),1)),"") -> 80.5 | U18: =IFERROR(IF(INDEX(data_wkly!U:U,MATCH($B18,data_wkly!$C:$C,0),1)=0,"",INDEX(data_wkly!U:U,MATCH($B18,data_wkly!$C:$C,0),1)),"") -> 11.1 | V18: =IF(M18="","",AO18) -> 2 | W18: =IFERROR(IF(INDEX(data_wkly!W:W,MATCH($B18,data_wkly!$C:$C,0),1)=0,"",INDEX(data_wkly!W:W,MATCH($B18,data_wkly!$C:$C,0),1)),"") -> 133.9795 | X18: =IFERROR(IF(INDEX(data_wkly!X:X,MATCH($B18,data_wkly!$C:$C,0),1)=0,"",INDEX(data_wkly!X:X,MATCH($B18,data_wkly!$C:$C,0),1)),"") -> -0.11821709 | Y18: =IFERROR(IF(INDEX(data_wkly!Y:Y,MATCH($B18,data_wkly!$C:$C,0),1)=0,"",INDEX(data_wkly!Y:Y,MATCH($B18,data_wkly!$C:$C,0),1)),"") -> 134.25 | Z18: =IFERROR(IF(INDEX(data_wkly!Z:Z,MATCH($B18,data_wkly!$C:$C,0),1)=0,"",INDEX(data_wkly!Z:Z,MATCH($B18,data_wkly!$C:$C,0),1)),"") -> -0.11 | AA18: =IFERROR(IF(INDEX(data_wkly!AA:AA,MATCH($B18,data_wkly!$C:$C,0),1)=0,"",INDEX(data_wkly!AA:AA,MATCH($B18,data_wkly!$C:$C,0),1)),"") -> 137.06 | AB18: =IFERROR(IF(INDEX(data_wkly!AB:AB,MATCH($B18,data_wkly!$C:$C,0),1)=0,"",INDEX(data_wkly!AB:AB,MATCH($B18,data_wkly!$C:$C,0),1)),"") -> -0.46 | AC18: =IFERROR(IF(INDEX(data_wkly!AC:AC,MATCH($B18,data_wkly!$C:$C,0),1)=0,"",INDEX(data_wkly!AC:AC,MATCH($B18,data_wkly!$C:$C,0),1)),"") -> 135.58 | AD18: =IFERROR(IF(INDEX(data_wkly!AD:AD,MATCH($B18,data_wkly!$C:$C,0),1)=0,"",INDEX(data_wkly!AD:AD,MATCH($B18,data_wkly!$C:$C,0),1)),"") -> -0.67 | AE18: =IF(W18="","",AO18) -> 2 | AF18: =IFERROR(IF(INDEX(data_wkly!AF:AF,MATCH($B18,data_wkly!$C:$C,0),1)=0,"",INDEX(data_wkly!AF:AF,MATCH($B18,data_wkly!$C:$C,0),1)),"") -> 164.01 | AG18: =IFERROR(IF(AF18="","",INDEX(data_wkly!AG:AG,MATCH($B18,data_wkly!$C:$C,0),1)),"") -> 0.11 | AH18: =IFERROR(IF(INDEX(data_wkly!AH:AH,MATCH($B18,data_wkly!$C:$C,0),1)=0,"",INDEX(data_wkly!AH:AH,MATCH($B18,data_wkly!$C:$C,0),1)),"") -> 151.98667 | AI18: =IFERROR(IF(INDEX(data_wkly!AI:AI,MATCH($B18,data_wkly!$C:$C,0),1)=0,"",INDEX(data_wkly!AI:AI,MATCH($B18,data_wkly!$C:$C,0),1)),"") -> 161.05 | AJ18: =IFERROR(IF(AI18="","",INDEX(data_wkly!AJ:AJ,MATCH($B18,data_wkly!$C:$C,0),1)),"") -> 0.11 | AK18: =IFERROR(IF(INDEX(data_wkly!AK:AK,MATCH($B18,data_wkly!$C:$C,0),1)=0,"",INDEX(data_wkly!AK:AK,MATCH($B18,data_wkly!$C:$C,0),1)),"") -> 149.25 | AL18: =IFERROR(IF(INDEX(data_wkly!AL:AL,MATCH($B18,data_wkly!$C:$C,0),1)=0,"",INDEX(data_wkly!AL:AL,MATCH($B18,data_wkly!$C:$C,0),1)),"") -> 80.02 | AM18: =IFERROR(IF(INDEX(data_wkly!AM:AM,MATCH($B18,data_wkly!$C:$C,0),1)=0,"",INDEX(data_wkly!AM:AM,MATCH($B18,data_wkly!$C:$C,0),1)),"") -> 10.9 | AN18: =IF(AF18="","",AO18) -> 2 | AO18: =AO16 -> 2
